Workbook

Sheet 매출
A1: 검정색 부분은 직접 작성 정산ID = 날짜+업체명+플랫폼 ex)260106 누카 네이버 업체명 = 누카 제품명 = 견적서 내의 제품명 기재
A2: 정산ID | B2: 업체명 | C2: 진행비 | D2: 진행 수량 | E2: 진행비+vat | F2: 진행비 총 공급가액 | G2: 진행비 총 입금액(+vat) | H2: 제품명 | I2: 제품 수량 | J2: 제품비 | K2: 제품비+vat | L2: 제품별 공급가액 | M2: 제품별 총 입금액(+vat) | N2: 제품비 총 공급가액 | O2: 제품비 총 입금액(+vat) | P2: 택배대행단가 | Q2: 택배 수량 | R2: 택배대행단가(+vat) | S2: 택배대행 총 공급가 | T2: 택배대행 총 입금액(+vat) | U2: 첫행(숨김)
A3: 260106조이쿠팡 | B3: 조이 | C3: 2500 | D3: 5 | E3: =IF(C3="","",C3*1.1) -> 2750 | F3: =IF(AND(C3<>"",D3<>""),C3*D3,"") -> 12500 | G3: =IF(F3="","",F3*1.1) -> 13750 | H3: 제품명모름 | I3: 5 | J3: 19840 | K3: =IF(J3="","",J3*1.1) -> 21824 | L3: =IF(AND(J3<>"",I3<>""),J3*I3,"") -> 99200 | M3: =IF(L3="","",L3*1.1) -> 109120 | N3: =IF(U3=1,SUMIFS($L:$L,$A:$A,$A3),"") -> 99200 | O3: =IF(U3=1,SUMIFS($M:$M,$A:$A,$A3),"") -> 109120 | R3: =IF(P3="","",P3*1.1) | S3: =IF(AND(P3<>"",Q3<>""),P3*Q3,"") | T3: =IF(S3="","",S3*1.1) | U3: =IF(A3="","",IF(COUNTIF($A$3:A3,A3)=1,1,0)) -> 1
A4: 260106넬리브쿠팡 | B4: 넬리브 | C4: 2500 | D4: 10 | E4: =IF(C4="","",C4*1.1) -> 2750 | F4: =IF(AND(C4<>"",D4<>""),C4*D4,"") -> 25000 | G4: =IF(F4="","",F4*1.1) -> 27500 | H4: 제품명모름 | I4: 10 | J4: 35000 | K4: =IF(J4="","",J4*1.1) -> 38500 | L4: =IF(AND(J4<>"",I4<>""),J4*I4,"") -> 350000 | M4: =IF(L4="","",L4*1.1) -> 385000 | N4: =IF(U4=1,SUMIFS($L:$L,$A:$A,$A4),"") -> 350000 | O4: =IF(U4=1,SUMIFS($M:$M,$A:$A,$A4),"") -> 385000 | R4: =IF(P4="","",P4*1.1) | S4: =IF(AND(P4<>"",Q4<>""),P4*Q4,"") | T4: =IF(S4="","",S4*1.1) | U4: =IF(A4="","",IF(COUNTIF($A$3:A4,A4)=1,1,0)) -> 1
A5: 260106블풍쿠팡 | B5: 블라우풍트 | C5: 2000 | D5: 30 | E5: =IF(C5="","",C5*1.1) -> 2200 | F5: =IF(AND(C5<>"",D5<>""),C5*D5,"") -> 60000 | G5: =IF(F5="","",F5*1.1) -> 66000 | H5: BLP-HMD5000W | I5: 30 | J5: 28900 | K5: =IF(J5="","",J5*1.1) -> 31790 | L5: =IF(AND(J5<>"",I5<>""),J5*I5,"") -> 867000 | M5: =IF(L5="","",L5*1.1) -> 953700 | N5: =IF(U5=1,SUMIFS($L:$L,$A:$A,$A5),"") -> 867000 | O5: =IF(U5=1,SUMIFS($M:$M,$A:$A,$A5),"") -> 953700 | R5: =IF(P5="","",P5*1.1) | S5: =IF(AND(P5<>"",Q5<>""),P5*Q5,"") | T5: =IF(S5="","",S5*1.1) | U5: =IF(A5="","",IF(COUNTIF($A$3:A5,A5)=1,1,0)) -> 1
A6: 260106블풍2쿠팡 | B6: 블라우풍트 | C6: 2000 | D6: 50 | E6: =IF(C6="","",C6*1.1) -> 2200 | F6: =IF(AND(C6<>"",D6<>""),C6*D6,"") -> 100000 | G6: =IF(F6="","",F6*1.1) -> 110000 | H6: BLP-ES802S | I6: 50 | J6: 49800 | K6: =IF(J6="","",J6*1.1) -> 54780 | L6: =IF(AND(J6<>"",I6<>""),J6*I6,"") -> 2490000 | M6: =IF(L6="","",L6*1.1) -> 2739000 | N6: =IF(U6=1,SUMIFS($L:$L,$A:$A,$A6),"") -> 2490000 | O6: =IF(U6=1,SUMIFS($M:$M,$A:$A,$A6),"") -> 2739000 | R6: =IF(P6="","",P6*1.1) | S6: =IF(AND(P6<>"",Q6<>""),P6*Q6,"") | T6: =IF(S6="","",S6*1.1) | U6: =IF(A6="","",IF(COUNTIF($A$3:A6,A6)=1,1,0)) -> 1
A7: 260106포뷰트올영 | B7: 포뷰트 | C7: 1500 | D7: 100 | E7: =IF(C7="","",C7*1.1) -> 1650 | F7: =IF(AND(C7<>"",D7<>""),C7*D7,"") -> 150000 | G7: =IF(F7="","",F7*1.1) -> 165000 | H7: 두피앰플 | I7: 100 | J7: 21800 | K7: =IF(J7="","",J7*1.1) -> 23980 | L7: =IF(AND(J7<>"",I7<>""),J7*I7,"") -> 2180000 | M7: =IF(L7="","",L7*1.1) -> 2398000 | N7: =IF(U7=1,SUMIFS($L:$L,$A:$A,$A7),"") -> 2180000 | O7: =IF(U7=1,SUMIFS($M:$M,$A:$A,$A7),"") -> 2398000 | R7: =IF(P7="","",P7*1.1) | S7: =IF(AND(P7<>"",Q7<>""),P7*Q7,"") | T7: =IF(S7="","",S7*1.1) | U7: =IF(A7="","",IF(COUNTIF($A$3:A7,A7)=1,1,0)) -> 1
A8: 260106더포레쿠팡 | B8: 더포레 | C8: 2500 | D8: 80 | E8: =IF(C8="","",C8*1.1) -> 2750 | F8: =IF(AND(C8<>"",D8<>""),C8*D8,"") -> 200000 | G8: =IF(F8="","",F8*1.1) -> 220000 | H8: 깍두기 | I8: 30 | J8: 8700 | K8: =IF(J8="","",J8*1.1) -> 9570 | L8: =IF(AND(J8<>"",I8<>""),J8*I8,"") -> 261000 | M8: =IF(L8="","",L8*1.1) -> 287100 | N8: =IF(U8=1,SUMIFS($L:$L,$A:$A,$A8),"") -> 826000 | O8: =IF(U8=1,SUMIFS($M:$M,$A:$A,$A8),"") -> 908600 | R8: =IF(P8="","",P8*1.1) | S8: =IF(AND(P8<>"",Q8<>""),P8*Q8,"") | T8: =IF(S8="","",S8*1.1) | U8: =IF(A8="","",IF(COUNTIF($A$3:A8,A8)=1,1,0)) -> 1
A9: 260106더포레쿠팡 | B9: 더포레 | E9: =IF(C9="","",C9*1.1) | F9: =IF(AND(C9<>"",D9<>""),C9*D9,"") | G9: =IF(F9="","",F9*1.1) | H9: 멸치 | I9: 30 | J9: 9300 | K9: =IF(J9="","",J9*1.1) -> 10230 | L9: =IF(AND(J9<>"",I9<>""),J9*I9,"") -> 279000 | M9: =IF(L9="","",L9*1.1) -> 306900 | N9: =IF(U9=1,SUMIFS($L:$L,$A:$A,$A9),"") | O9: =IF(U9=1,SUMIFS($M:$M,$A:$A,$A9),"") | R9: =IF(P9="","",P9*1.1) | S9: =IF(AND(P9<>"",Q9<>""),P9*Q9,"") | T9: =IF(S9="","",S9*1.1) | U9: =IF(A9="","",IF(COUNTIF($A$3:A9,A9)=1,1,0)) -> 0
A10: 260106더포레쿠팡 | B10: 더포레 | E10: =IF(C10="","",C10*1.1) | F10: =IF(AND(C10<>"",D10<>""),C10*D10,"") | G10: =IF(F10="","",F10*1.1) | H10: 오이소박이 | I10: 20 | J10: 14300 | K10: =IF(J10="","",J10*1.1) -> 15730 | L10: =IF(AND(J10<>"",I10<>""),J10*I10,"") -> 286000 | M10: =IF(L10="","",L10*1.1) -> 314600 | N10: =IF(U10=1,SUMIFS($L:$L,$A:$A,$A10),"") | O10: =IF(U10=1,SUMIFS($M:$M,$A:$A,$A10),"") | R10: =IF(P10="","",P10*1.1) | S10: =IF(AND(P10<>"",Q10<>""),P10*Q10,"") | T10: =IF(S10="","",S10*1.1) | U10: =IF(A10="","",IF(COUNTIF($A$3:A10,A10)=1,1,0)) -> 0
A11: 260105케이에스쿠팡 | B11: 케이에스 | C11: 2500 | D11: 100 | E11: =IF(C11="","",C11*1.1) -> 2750 | F11: =IF(AND(C11<>"",D11<>""),C11*D11,"") -> 250000 | G11: =IF(F11="","",F11*1.1) -> 275000 | H11: 베르베린 | I11: 100 | J11: 19500 | K11: =IF(J11="","",J11*1.1) -> 21450 | L11: =IF(AND(J11<>"",I11<>""),J11*I11,"") -> 1950000 | M11: =IF(L11="","",L11*1.1) -> 2145000 | N11: =IF(U11=1,SUMIFS($L:$L,$A:$A,$A11),"") -> 1950000 | O11: =IF(U11=1,SUMIFS($M:$M,$A:$A,$A11),"") -> 2145000 | R11: =IF(P11="","",P11*1.1) | S11: =IF(AND(P11<>"",Q11<>""),P11*Q11,"") | T11: =IF(S11="","",S11*1.1) | U11: =IF(A11="","",IF(COUNTIF($A$3:A11,A11)=1,1,0)) -> 1
A12: 260105케이에스2쿠팡 | B12: 케이에스 | C12: 2500 | D12: 100 | E12: =IF(C12="","",C12*1.1) -> 2750 | F12: =IF(AND(C12<>"",D12<>""),C12*D12,"") -> 250000 | G12: =IF(F12="","",F12*1.1) -> 275000 | H12: 위고핏 | I12: 100 | J12: 26500 | K12: =IF(J12="","",J12*1.1) -> 29150 | L12: =IF(AND(J12<>"",I12<>""),J12*I12,"") -> 2650000 | M12: =IF(L12="","",L12*1.1) -> 2915000 | N12: =IF(U12=1,SUMIFS($L:$L,$A:$A,$A12),"") -> 2650000 | O12: =IF(U12=1,SUMIFS($M:$M,$A:$A,$A12),"") -> 2915000 | R12: =IF(P12="","",P12*1.1) | S12: =IF(AND(P12<>"",Q12<>""),P12*Q12,"") | T12: =IF(S12="","",S12*1.1) | U12: =IF(A12="","",IF(COUNTIF($A$3:A12,A12)=1,1,0)) -> 1
A13: 260106와이에이쿠팡 | B13: 와이에이 | C13: 2500 | D13: 60 | E13: =IF(C13="","",C13*1.1) -> 2750 | F13: =IF(AND(C13<>"",D13<>""),C13*D13,"") -> 150000 | G13: =IF(F13="","",F13*1.1) -> 165000 | H13: 제품명모름 | I13: 60 | J13: 15900 | K13: =IF(J13="","",J13*1.1) -> 17490 | L13: =IF(AND(J13<>"",I13<>""),J13*I13,"") -> 954000 | M13: =IF(L13="","",L13*1.1) -> 1049400 | N13: =IF(U13=1,SUMIFS($L:$L,$A:$A,$A13),"") -> 954000 | O13: =IF(U13=1,SUMIFS($M:$M,$A:$A,$A13),"") -> 1049400 | R13: =IF(P13="","",P13*1.1) | S13: =IF(AND(P13<>"",Q13<>""),P13*Q13,"") | T13: =IF(S13="","",S13*1.1) | U13: =IF(A13="","",IF(COUNTIF($A$3:A13,A13)=1,1,0)) -> 1
A14: 260105미올로쿠팡 | B14: 미올로 | C14: 2500 | D14: 100 | E14: =IF(C14="","",C14*1.1) -> 2750 | F14: =IF(AND(C14<>"",D14<>""),C14*D14,"") -> 250000 | G14: =IF(F14="","",F14*1.1) -> 275000 | H14: W7 | I14: 100 | J14: 9900 | K14: =IF(J14="","",J14*1.1) -> 10890 | L14: =IF(AND(J14<>"",I14<>""),J14*I14,"") -> 990000 | M14: =IF(L14="","",L14*1.1) -> 1089000 | N14: =IF(U14=1,SUMIFS($L:$L,$A:$A,$A14),"") -> 990000 | O14: =IF(U14=1,SUMIFS($M:$M,$A:$A,$A14),"") -> 1089000 | R14: =IF(P14="","",P14*1.1) | S14: =IF(AND(P14<>"",Q14<>""),P14*Q14,"") | T14: =IF(S14="","",S14*1.1) | U14: =IF(A14="","",IF(COUNTIF($A$3:A14,A14)=1,1,0)) -> 1
A15: 260105미올로2쿠팡 | B15: 미올로 | C15: 2500 | D15: 100 | E15: =IF(C15="","",C15*1.1) -> 2750 | F15: =IF(AND(C15<>"",D15<>""),C15*D15,"") -> 250000 | G15: =IF(F15="","",F15*1.1) -> 275000 | H15: B7 | I15: 100 | J15: 9900 | K15: =IF(J15="","",J15*1.1) -> 10890 | L15: =IF(AND(J15<>"",I15<>""),J15*I15,"") -> 990000 | M15: =IF(L15="","",L15*1.1) -> 1089000 | N15: =IF(U15=1,SUMIFS($L:$L,$A:$A,$A15),"") -> 990000 | O15: =IF(U15=1,SUMIFS($M:$M,$A:$A,$A15),"") -> 1089000 | R15: =IF(P15="","",P15*1.1) | S15: =IF(AND(P15<>"",Q15<>""),P15*Q15,"") | T15: =IF(S15="","",S15*1.1) | U15: =IF(A15="","",IF(COUNTIF($A$3:A15,A15)=1,1,0)) -> 1
A16: 260106꿈꾸던쿠팡 | B16: 꿈꾸던 | C16: 2500 | D16: 10 | E16: =IF(C16="","",C16*1.1) -> 2750 | F16: =IF(AND(C16<>"",D16<>""),C16*D16,"") -> 25000 | G16: =IF(F16="","",F16*1.1) -> 27500 | H16: 제품명모름 | I16: 10 | J16: 8700 | K16: =IF(J16="","",J16*1.1) -> 9570 | L16: =IF(AND(J16<>"",I16<>""),J16*I16,"") -> 87000 | M16: =IF(L16="","",L16*1.1) -> 95700 | N16: =IF(U16=1,SUMIFS($L:$L,$A:$A,$A16),"") -> 87000 | O16: =IF(U16=1,SUMIFS($M:$M,$A:$A,$A16),"") -> 95700 | R16: =IF(P16="","",P16*1.1) | S16: =IF(AND(P16<>"",Q16<>""),P16*Q16,"") | T16: =IF(S16="","",S16*1.1) | U16: =IF(A16="","",IF(COUNTIF($A$3:A16,A16)=1,1,0)) -> 1
A17: 260106닥터메타쿠팡 | B17: 닥터메타 | C17: 2500 | D17: 20 | E17: =IF(C17="","",C17*1.1) -> 2750 | F17: =IF(AND(C17<>"",D17<>""),C17*D17,"") -> 50000 | G17: =IF(F17="","",F17*1.1) -> 55000 | H17: 제품명모름 | I17: 10 | J17: 38000 | K17: =IF(J17="","",J17*1.1) -> 41800 | L17: =IF(AND(J17<>"",I17<>""),J17*I17,"") -> 380000 | M17: =IF(L17="","",L17*1.1) -> 418000 | N17: =IF(U17=1,SUMIFS($L:$L,$A:$A,$A17),"") -> 700000 | O17: =IF(U17=1,SUMIFS($M:$M,$A:$A,$A17),"") -> 770000 | R17: =IF(P17="","",P17*1.1) | S17: =IF(AND(P17<>"",Q17<>""),P17*Q17,"") | T17: =IF(S17="","",S17*1.1) | U17: =IF(A17="","",IF(COUNTIF($A$3:A17,A17)=1,1,0)) -> 1
A18: 260106닥터메타쿠팡 | E18: =IF(C18="","",C18*1.1) | F18: =IF(AND(C18<>"",D18<>""),C18*D18,"") | G18: =IF(F18="","",F18*1.1) | H18: 제품명모름 | I18: 5 | J18: 35000 | K18: =IF(J18="","",J18*1.1) -> 38500 | L18: =IF(AND(J18<>"",I18<>""),J18*I18,"") -> 175000 | M18: =IF(L18="","",L18*1.1) -> 192500 | N18: =IF(U18=1,SUMIFS($L:$L,$A:$A,$A18),"") | O18: =IF(U18=1,SUMIFS($M:$M,$A:$A,$A18),"") | R18: =IF(P18="","",P18*1.1) | S18: =IF(AND(P18<>"",Q18<>""),P18*Q18,"") | T18: =IF(S18="","",S18*1.1) | U18: =IF(A18="","",IF(COUNTIF($A$3:A18,A18)=1,1,0)) -> 0
A19: 260106닥터메타쿠팡 | E19: =IF(C19="","",C19*1.1) | F19: =IF(AND(C19<>"",D19<>""),C19*D19,"") | G19: =IF(F19="","",F19*1.1) | H19: 제품명모름 | I19: 5 | J19: 29000 | K19: =IF(J19="","",J19*1.1) -> 31900 | L19: =IF(AND(J19<>"",I19<>""),J19*I19,"") -> 145000 | M19: =IF(L19="","",L19*1.1) -> 159500 | N19: =IF(U19=1,SUMIFS($L:$L,$A:$A,$A19),"") | O19: =IF(U19=1,SUMIFS($M:$M,$A:$A,$A19),"") | R19: =IF(P19="","",P19*1.1) | S19: =IF(AND(P19<>"",Q19<>""),P19*Q19,"") | T19: =IF(S19="","",S19*1.1) | U19: =IF(A19="","",IF(COUNTIF($A$3:A19,A19)=1,1,0)) -> 0
A20: 260106오브제 | B20: 오브제 | C20: 800 | D20: 855 | E20: =IF(C20="","",C20*1.1) -> 880 | F20: =IF(AND(C20<>"",D20<>""),C20*D20,"") -> 684000 | G20: =IF(F20="","",F20*1.1) -> 752400 | H20: 12/31 오브제 포어 제로 오일 컨트롤 선크림 SPF50+ PA++++, 50ml, 1개 | I20: 10 | J20: 17900 | K20: =IF(J20="","",J20*1.1) -> 19690 | L20: =IF(AND(J20<>"",I20<>""),J20*I20,"") -> 179000 | M20: =IF(L20="","",L20*1.1) -> 196900 | N20: =IF(U20=1,SUMIFS($L:$L,$A:$A,$A20),"") -> 19068000 | O20: =IF(U20=1,SUMIFS($M:$M,$A:$A,$A20),"") -> 20974800 | R20: =IF(P20="","",P20*1.1) | S20: =IF(AND(P20<>"",Q20<>""),P20*Q20,"") | T20: =IF(S20="","",S20*1.1) | U20: =IF(A20="","",IF(COUNTIF($A$3:A20,A20)=1,1,0)) -> 1
A21: 260106오브제 | B21: 오브제 | E21: =IF(C21="","",C21*1.1) | F21: =IF(AND(C21<>"",D21<>""),C21*D21,"") | G21: =IF(F21="","",F21*1.1) | H21: 12/31 오브제 올인원 쿨 픽싱 미스트, 1개, 100ml | I21: 5 | J21: 15790 | K21: =IF(J21="","",J21*1.1) -> 17369 | L21: =IF(AND(J21<>"",I21<>""),J21*I21,"") -> 78950 | M21: =IF(L21="","",L21*1.1) -> 86845 | N21: =IF(U21=1,SUMIFS($L:$L,$A:$A,$A21),"") | O21: =IF(U21=1,SUMIFS($M:$M,$A:$A,$A21),"") | R21: =IF(P21="","",P21*1.1) | S21: =IF(AND(P21<>"",Q21<>""),P21*Q21,"") | T21: =IF(S21="","",S21*1.1) | U21: =IF(A21="","",IF(COUNTIF($A$3:A21,A21)=1,1,0)) -> 0
A22: 260106오브제 | B22: 오브제 | E22: =IF(C22="","",C22*1.1) | F22: =IF(AND(C22<>"",D22<>""),C22*D22,"") | G22: =IF(F22="","",F22*1.1) | H22: 12/31 오브제 올인원 더블 에센스 100ml | I22: 5 | J22: 25300 | K22: =IF(J22="","",J22*1.1) -> 27830 | L22: =IF(AND(J22<>"",I22<>""),J22*I22,"") -> 126500 | M22: =IF(L22="","",L22*1.1) -> 139150 | N22: =IF(U22=1,SUMIFS($L:$L,$A:$A,$A22),"") | O22: =IF(U22=1,SUMIFS($M:$M,$A:$A,$A22),"") | R22: =IF(P22="","",P22*1.1) | S22: =IF(AND(P22<>"",Q22<>""),P22*Q22,"") | T22: =IF(S22="","",S22*1.1) | U22: =IF(A22="","",IF(COUNTIF($A$3:A22,A22)=1,1,0)) -> 0
A23: 260106오브제 | B23: 오브제 | E23: =IF(C23="","",C23*1.1) | F23: =IF(AND(C23<>"",D23<>""),C23*D23,"") | G23: =IF(F23="","",F23*1.1) | H23: 12/31 오브제 오일 컨트롤 피니셔 5g 기름종이 팩트 파우더 | I23: 10 | J23: 16400 | K23: =IF(J23="","",J23*1.1) -> 18040 | L23: =IF(AND(J23<>"",I23<>""),J23*I23,"") -> 164000 | M23: =IF(L23="","",L23*1.1) -> 180400 | N23: =IF(U23=1,SUMIFS($L:$L,$A:$A,$A23),"") | O23: =IF(U23=1,SUMIFS($M:$M,$A:$A,$A23),"") | R23: =IF(P23="","",P23*1.1) | S23: =IF(AND(P23<>"",Q23<>""),P23*Q23,"") | T23: =IF(S23="","",S23*1.1) | U23: =IF(A23="","",IF(COUNTIF($A$3:A23,A23)=1,1,0)) -> 0
A24: 260106오브제 | B24: 오브제 | E24: =IF(C24="","",C24*1.1) | F24: =IF(AND(C24<>"",D24<>""),C24*D24,"") | G24: =IF(F24="","",F24*1.1) | H24: 12/31 오브제 씬 스틸 컨실러 5g | I24: 3 | J24: 14900 | K24: =IF(J24="","",J24*1.1) -> 16390 | L24: =IF(AND(J24<>"",I24<>""),J24*I24,"") -> 44700 | M24: =IF(L24="","",L24*1.1) -> 49170 | N24: =IF(U24=1,SUMIFS($L:$L,$A:$A,$A24),"") | O24: =IF(U24=1,SUMIFS($M:$M,$A:$A,$A24),"") | R24: =IF(P24="","",P24*1.1) | S24: =IF(AND(P24<>"",Q24<>""),P24*Q24,"") | T24: =IF(S24="","",S24*1.1) | U24: =IF(A24="","",IF(COUNTIF($A$3:A24,A24)=1,1,0)) -> 0
A25: 260106오브제 | B25: 오브제 | E25: =IF(C25="","",C25*1.1) | F25: =IF(AND(C25<>"",D25<>""),C25*D25,"") | G25: =IF(F25="","",F25*1.1) | H25: 12/31 오브제 씬 스틸 컨실러 5g | I25: 5 | J25: 14900 | K25: =IF(J25="","",J25*1.1) -> 16390 | L25: =IF(AND(J25<>"",I25<>""),J25*I25,"") -> 74500 | M25: =IF(L25="","",L25*1.1) -> 81950 | N25: =IF(U25=1,SUMIFS($L:$L,$A:$A,$A25),"") | O25: =IF(U25=1,SUMIFS($M:$M,$A:$A,$A25),"") | R25: =IF(P25="","",P25*1.1) | S25: =IF(AND(P25<>"",Q25<>""),P25*Q25,"") | T25: =IF(S25="","",S25*1.1) | U25: =IF(A25="","",IF(COUNTIF($A$3:A25,A25)=1,1,0)) -> 0
A26: 260106오브제 | B26: 오브제 | E26: =IF(C26="","",C26*1.1) | F26: =IF(AND(C26<>"",D26<>""),C26*D26,"") | G26: =IF(F26="","",F26*1.1) | H26: 12/31 오브제 무드 체인지 립밤, 웜 오렌지, 1개 | I26: 15 | J26: 11500 | K26: =IF(J26="","",J26*1.1) -> 12650 | L26: =IF(AND(J26<>"",I26<>""),J26*I26,"") -> 172500 | M26: =IF(L26="","",L26*1.1) -> 189750 | N26: =IF(U26=1,SUMIFS($L:$L,$A:$A,$A26),"") | O26: =IF(U26=1,SUMIFS($M:$M,$A:$A,$A26),"") | R26: =IF(P26="","",P26*1.1) | S26: =IF(AND(P26<>"",Q26<>""),P26*Q26,"") | T26: =IF(S26="","",S26*1.1) | U26: =IF(A26="","",IF(COUNTIF($A$3:A26,A26)=1,1,0)) -> 0
A27: 260106오브제 | B27: 오브제 | E27: =IF(C27="","",C27*1.1) | F27: =IF(AND(C27<>"",D27<>""),C27*D27,"") | G27: =IF(F27="","",F27*1.1) | H27: 12/29 오브제 포어 제로 필링 토너 310ml + 오일 컨트롤 로션 70ml + 클레이팩 100ml 기초 3종 세트 | I27: 15 | J27: 49900 | K27: =IF(J27="","",J27*1.1) -> 54890 | L27: =IF(AND(J27<>"",I27<>""),J27*I27,"") -> 748500 | M27: =IF(L27="","",L27*1.1) -> 823350 | N27: =IF(U27=1,SUMIFS($L:$L,$A:$A,$A27),"") | O27: =IF(U27=1,SUMIFS($M:$M,$A:$A,$A27),"") | R27: =IF(P27="","",P27*1.1) | S27: =IF(AND(P27<>"",Q27<>""),P27*Q27,"") | T27: =IF(S27="","",S27*1.1) | U27: =IF(A27="","",IF(COUNTIF($A$3:A27,A27)=1,1,0)) -> 0
A28: 260106오브제 | B28: 오브제 | E28: =IF(C28="","",C28*1.1) | F28: =IF(AND(C28<>"",D28<>""),C28*D28,"") | G28: =IF(F28="","",F28*1.1) | H28: 12/27 오브제 무드 체인지 립밤 (3종 택1) | I28: 18 | J28: 11500 | K28: =IF(J28="","",J28*1.1) -> 12650 | L28: =IF(AND(J28<>"",I28<>""),J28*I28,"") -> 207000 | M28: =IF(L28="","",L28*1.1) -> 227700 | N28: =IF(U28=1,SUMIFS($L:$L,$A:$A,$A28),"") | O28: =IF(U28=1,SUMIFS($M:$M,$A:$A,$A28),"") | R28: =IF(P28="","",P28*1.1) | S28: =IF(AND(P28<>"",Q28<>""),P28*Q28,"") | T28: =IF(S28="","",S28*1.1) | U28: =IF(A28="","",IF(COUNTIF($A$3:A28,A28)=1,1,0)) -> 0
A29: 260106오브제 | B29: 오브제 | E29: =IF(C29="","",C29*1.1) | F29: =IF(AND(C29<>"",D29<>""),C29*D29,"") | G29: =IF(F29="","",F29*1.1) | H29: 12/25 오브제 모이스처 프로틴 장벽 크림, 70ml, 2개 | I29: 5 | J29: 35800 | K29: =IF(J29="","",J29*1.1) -> 39380 | L29: =IF(AND(J29<>"",I29<>""),J29*I29,"") -> 179000 | M29: =IF(L29="","",L29*1.1) -> 196900 | N29: =IF(U29=1,SUMIFS($L:$L,$A:$A,$A29),"") | O29: =IF(U29=1,SUMIFS($M:$M,$A:$A,$A29),"") | R29: =IF(P29="","",P29*1.1) | S29: =IF(AND(P29<>"",Q29<>""),P29*Q29,"") | T29: =IF(S29="","",S29*1.1) | U29: =IF(A29="","",IF(COUNTIF($A$3:A29,A29)=1,1,0)) -> 0
A30: 260106오브제 | B30: 오브제 | E30: =IF(C30="","",C30*1.1) | F30: =IF(AND(C30<>"",D30<>""),C30*D30,"") | G30: =IF(F30="","",F30*1.1) | H30: 12/24 오브제 포어 제로 무스 클레이 팩 100ml | I30: 15 | J30: 21400 | K30: =IF(J30="","",J30*1.1) -> 23540 | L30: =IF(AND(J30<>"",I30<>""),J30*I30,"") -> 321000 | M30: =IF(L30="","",L30*1.1) -> 353100 | N30: =IF(U30=1,SUMIFS($L:$L,$A:$A,$A30),"") | O30: =IF(U30=1,SUMIFS($M:$M,$A:$A,$A30),"") | R30: =IF(P30="","",P30*1.1) | S30: =IF(AND(P30<>"",Q30<>""),P30*Q30,"") | T30: =IF(S30="","",S30*1.1) | U30: =IF(A30="","",IF(COUNTIF($A$3:A30,A30)=1,1,0)) -> 0
A31: 260106오브제 | B31: 오브제 | E31: =IF(C31="","",C31*1.1) | F31: =IF(AND(C31<>"",D31<>""),C31*D31,"") | G31: =IF(F31="","",F31*1.1) | H31: 12/24 오브제 오브제 맥스 워터풀 선크림 대용량 저자극 피부진정 올인원 SPF50+ PA++++, 1개, 300ml | I31: 5 | J31: 24900 | K31: =IF(J31="","",J31*1.1) -> 27390 | L31: =IF(AND(J31<>"",I31<>""),J31*I31,"") -> 124500 | M31: =IF(L31="","",L31*1.1) -> 136950 | N31: =IF(U31=1,SUMIFS($L:$L,$A:$A,$A31),"") | O31: =IF(U31=1,SUMIFS($M:$M,$A:$A,$A31),"") | R31: =IF(P31="","",P31*1.1) | S31: =IF(AND(P31<>"",Q31<>""),P31*Q31,"") | T31: =IF(S31="","",S31*1.1) | U31: =IF(A31="","",IF(COUNTIF($A$3:A31,A31)=1,1,0)) -> 0
A32: 260106오브제 | B32: 오브제 | E32: =IF(C32="","",C32*1.1) | F32: =IF(AND(C32<>"",D32<>""),C32*D32,"") | G32: =IF(F32="","",F32*1.1) | H32: 12/24 오브제 오브제 맥스 올인원 워시 남성용 페이스 바디 클렌저 샴푸, 1개, 500ml | I32: 6 | J32: 18900 | K32: =IF(J32="","",J32*1.1) -> 20790 | L32: =IF(AND(J32<>"",I32<>""),J32*I32,"") -> 113400 | M32: =IF(L32="","",L32*1.1) -> 124740 | N32: =IF(U32=1,SUMIFS($L:$L,$A:$A,$A32),"") | O32: =IF(U32=1,SUMIFS($M:$M,$A:$A,$A32),"") | R32: =IF(P32="","",P32*1.1) | S32: =IF(AND(P32<>"",Q32<>""),P32*Q32,"") | T32: =IF(S32="","",S32*1.1) | U32: =IF(A32="","",IF(COUNTIF($A$3:A32,A32)=1,1,0)) -> 0
... A62: 260106오브제 | B62: 오브제 | E62: =IF(C62="","",C62*1.1) | F62: =IF(AND(C62<>"",D62<>""),C62*D62,"") | G62: =IF(F62="","",F62*1.1) | H62: 1/1 오브제 내추럴 올인원 커버 로션 50g, 1개 | I62: 30 | J62: 25250 | K62: =IF(J62="","",J62*1.1) -> 27775 | L62: =IF(AND(J62<>"",I62<>""),J62*I62,"") -> 757500 | M62: =IF(L62="","",L62*1.1) -> 833250 | N62: =IF(U62=1,SUMIFS($L:$L,$A:$A,$A62),"") | O62: =IF(U62=1,SUMIFS($M:$M,$A:$A,$A62),"") | R62: =IF(P62="","",P62*1.1) | S62: =IF(AND(P62<>"",Q62<>""),P62*Q62,"") | T62: =IF(S62="","",S62*1.1) | U62: =IF(A62="","",IF(COUNTIF($A$3:A62,A62)=1,1,0)) -> 0
A63: 260106푸드올로지 | B63: 푸드올로지 | C63: 800 | D63: 1089 | E63: =IF(C63="","",C63*1.1) -> 880 | F63: =IF(AND(C63<>"",D63<>""),C63*D63,"") -> 871200 | G63: =IF(F63="","",F63*1.1) -> 958320 | H63: 12/31 푸드올로지 톡스올로지 클렌즈 비움, 450ml, 1개 | I63: 3 | J63: 28800 | K63: =IF(J63="","",J63*1.1) -> 31680 | L63: =IF(AND(J63<>"",I63<>""),J63*I63,"") -> 86400 | M63: =IF(L63="","",L63*1.1) -> 95040 | N63: =IF(U63=1,SUMIFS($L:$L,$A:$A,$A63),"") -> 31019310 | O63: =IF(U63=1,SUMIFS($M:$M,$A:$A,$A63),"") -> 34121241 | R63: =IF(P63="","",P63*1.1) | S63: =IF(AND(P63<>"",Q63<>""),P63*Q63,"") | T63: =IF(S63="","",S63*1.1) | U63: =IF(A63="","",IF(COUNTIF($A$3:A63,A63)=1,1,0)) -> 1
A64: 260106푸드올로지 | B64: 푸드올로지 | E64: =IF(C64="","",C64*1.1) | F64: =IF(AND(C64<>"",D64<>""),C64*D64,"") | G64: =IF(F64="","",F64*1.1) | H64: 12/31 푸드올로지 톡스올로지 48시간 CCA 클렌즈주스, 1L, 1개 | I64: 5 | J64: 24800 | K64: =IF(J64="","",J64*1.1) -> 27280 | L64: =IF(AND(J64<>"",I64<>""),J64*I64,"") -> 124000 | M64: =IF(L64="","",L64*1.1) -> 136400 | N64: =IF(U64=1,SUMIFS($L:$L,$A:$A,$A64),"") | O64: =IF(U64=1,SUMIFS($M:$M,$A:$A,$A64),"") | R64: =IF(P64="","",P64*1.1) | S64: =IF(AND(P64<>"",Q64<>""),P64*Q64,"") | T64: =IF(S64="","",S64*1.1) | U64: =IF(A64="","",IF(COUNTIF($A$3:A64,A64)=1,1,0)) -> 0
A65: 260106푸드올로지 | B65: 푸드올로지 | E65: =IF(C65="","",C65*1.1) | F65: =IF(AND(C65<>"",D65<>""),C65*D65,"") | G65: =IF(F65="","",F65*1.1) | H65: 12/31 푸드올로지 톡스올로지 48시간 CCA 클렌즈주스, 1L, 1개 | I65: 10 | J65: 24800 | K65: =IF(J65="","",J65*1.1) -> 27280 | L65: =IF(AND(J65<>"",I65<>""),J65*I65,"") -> 248000 | M65: =IF(L65="","",L65*1.1) -> 272800 | N65: =IF(U65=1,SUMIFS($L:$L,$A:$A,$A65),"") | O65: =IF(U65=1,SUMIFS($M:$M,$A:$A,$A65),"") | R65: =IF(P65="","",P65*1.1) | S65: =IF(AND(P65<>"",Q65<>""),P65*Q65,"") | T65: =IF(S65="","",S65*1.1) | U65: =IF(A65="","",IF(COUNTIF($A$3:A65,A65)=1,1,0)) -> 0
A66: 260106푸드올로지 | B66: 푸드올로지 | E66: =IF(C66="","",C66*1.1) | F66: =IF(AND(C66<>"",D66<>""),C66*D66,"") | G66: =IF(F66="","",F66*1.1) | H66: 12/31 푸드올로지 콜레올로지컷 프로 다이어트 보조제 39.6g, 66정, 1개 | I66: 5 | J66: 34190 | K66: =IF(J66="","",J66*1.1) -> 37609 | L66: =IF(AND(J66<>"",I66<>""),J66*I66,"") -> 170950 | M66: =IF(L66="","",L66*1.1) -> 188045 | N66: =IF(U66=1,SUMIFS($L:$L,$A:$A,$A66),"") | O66: =IF(U66=1,SUMIFS($M:$M,$A:$A,$A66),"") | R66: =IF(P66="","",P66*1.1) | S66: =IF(AND(P66<>"",Q66<>""),P66*Q66,"") | T66: =IF(S66="","",S66*1.1) | U66: =IF(A66="","",IF(COUNTIF($A$3:A66,A66)=1,1,0)) -> 0
A67: 260106푸드올로지 | B67: 푸드올로지 | E67: =IF(C67="","",C67*1.1) | F67: =IF(AND(C67<>"",D67<>""),C67*D67,"") | G67: =IF(F67="","",F67*1.1) | H67: 12/31 푸드올로지 콜레올로지컷 다이어트 유산균, 20정, 1개 | I67: 3 | J67: 29800 | K67: =IF(J67="","",J67*1.1) -> 32780 | L67: =IF(AND(J67<>"",I67<>""),J67*I67,"") -> 89400 | M67: =IF(L67="","",L67*1.1) -> 98340 | N67: =IF(U67=1,SUMIFS($L:$L,$A:$A,$A67),"") | O67: =IF(U67=1,SUMIFS($M:$M,$A:$A,$A67),"") | R67: =IF(P67="","",P67*1.1) | S67: =IF(AND(P67<>"",Q67<>""),P67*Q67,"") | T67: =IF(S67="","",S67*1.1) | U67: =IF(A67="","",IF(COUNTIF($A$3:A67,A67)=1,1,0)) -> 0
A68: 260106푸드올로지 | B68: 푸드올로지 | E68: =IF(C68="","",C68*1.1) | F68: =IF(AND(C68<>"",D68<>""),C68*D68,"") | G68: =IF(F68="","",F68*1.1) | H68: 12/31 푸드올로지 콜레 티 워터, 500ml, 12개 | I68: 3 | J68: 16900 | K68: =IF(J68="","",J68*1.1) -> 18590 | L68: =IF(AND(J68<>"",I68<>""),J68*I68,"") -> 50700 | M68: =IF(L68="","",L68*1.1) -> 55770 | N68: =IF(U68=1,SUMIFS($L:$L,$A:$A,$A68),"") | O68: =IF(U68=1,SUMIFS($M:$M,$A:$A,$A68),"") | R68: =IF(P68="","",P68*1.1) | S68: =IF(AND(P68<>"",Q68<>""),P68*Q68,"") | T68: =IF(S68="","",S68*1.1) | U68: =IF(A68="","",IF(COUNTIF($A$3:A68,A68)=1,1,0)) -> 0
A69: 260106푸드올로지 | B69: 푸드올로지 | E69: =IF(C69="","",C69*1.1) | F69: =IF(AND(C69<>"",D69<>""),C69*D69,"") | G69: =IF(F69="","",F69*1.1) | H69: 12/31 푸드올로지 콜라겐 센텔라 젤리, 1개, 10회분 | I69: 10 | J69: 22800 | K69: =IF(J69="","",J69*1.1) -> 25080 | L69: =IF(AND(J69<>"",I69<>""),J69*I69,"") -> 228000 | M69: =IF(L69="","",L69*1.1) -> 250800 | N69: =IF(U69=1,SUMIFS($L:$L,$A:$A,$A69),"") | O69: =IF(U69=1,SUMIFS($M:$M,$A:$A,$A69),"") | R69: =IF(P69="","",P69*1.1) | S69: =IF(AND(P69<>"",Q69<>""),P69*Q69,"") | T69: =IF(S69="","",S69*1.1) | U69: =IF(A69="","",IF(COUNTIF($A$3:A69,A69)=1,1,0)) -> 0
...

Sheet 지출
A1: 진행비(실비) = 리뷰 및 진행자 비용 합으로 작성
A2: 정산ID | B2: 업체명 | C2: 진행비(실비) | D2: 진행비 수량 | E2: 진행비 총 지출 | F2: 제품명 | G2: 제품 수량 | H2: 제품비(실비) | I2: 제품별 지출액 | J2: 제품비 총 지출액 | K2: 택배대행(실비)+vat(고정) | L2: 택배 수량 | M2: 택배대행 총 지출 | N2: 총 지출 액 | O2: 첫행(숨김)
A3: =매출!A3 -> 260106조이쿠팡 | B3: =매출!B3 -> 조이 | C3: 1000 | D3: =매출!D3 -> 5 | E3: =IF(AND(C3<>"",D3<>""),C3*D3,"") -> 5000 | F3: =매출!H3 -> 제품명모름 | G3: =매출!I3 -> 5 | H3: =매출!J3 -> 19840 | I3: =매출!L3 -> 99200 | J3: =IF(O3=1,SUMIFS($I:$I,$A:$A,$A3),"") -> 99200 | K3: =IF(O3=1,총정리!$B$19,"") -> 2750 | L3: =IF(O3=1,매출!Q3,"") -> 0 | M3: =IF(AND(K3<>"",L3<>""),K3*L3,"") -> 0 | N3: =IF(O3=1,E3+J3+M3,"") -> 104200 | O3: =매출!U3 -> 1
A4: =매출!A4 -> 260106넬리브쿠팡 | B4: =매출!B4 -> 넬리브 | C4: 3000 | D4: =매출!D4 -> 10 | E4: =IF(AND(C4<>"",D4<>""),C4*D4,"") -> 30000 | F4: =매출!H4 -> 제품명모름 | G4: =매출!I4 -> 10 | H4: =매출!J4 -> 35000 | I4: =매출!L4 -> 350000 | J4: =IF(O4=1,SUMIFS($I:$I,$A:$A,$A4),"") -> 350000 | K4: =IF(O4=1,총정리!$B$19,"") -> 2750 | L4: =IF(O4=1,매출!Q4,"") -> 0 | M4: =IF(AND(K4<>"",L4<>""),K4*L4,"") -> 0 | N4: =IF(O4=1,E4+J4+M4,"") -> 380000 | O4: =매출!U4 -> 1 | Q4: 황인호 빈박500원
A5: =매출!A5 -> 260106블풍쿠팡 | B5: =매출!B5 -> 블라우풍트 | C5: 1000 | D5: =매출!D5 -> 30 | E5: =IF(AND(C5<>"",D5<>""),C5*D5,"") -> 30000 | F5: =매출!H5 -> BLP-HMD5000W | G5: =매출!I5 -> 30 | H5: =매출!J5 -> 28900 | I5: =매출!L5 -> 867000 | J5: =IF(O5=1,SUMIFS($I:$I,$A:$A,$A5),"") -> 867000 | K5: =IF(O5=1,총정리!$B$19,"") -> 2750 | L5: =IF(O5=1,매출!Q5,"") -> 0 | M5: =IF(AND(K5<>"",L5<>""),K5*L5,"") -> 0 | N5: =IF(O5=1,E5+J5+M5,"") -> 897000 | O5: =매출!U5 -> 1
A6: =매출!A6 -> 260106블풍2쿠팡 | B6: =매출!B6 -> 블라우풍트 | C6: 1000 | D6: =매출!D6 -> 50 | E6: =IF(AND(C6<>"",D6<>""),C6*D6,"") -> 50000 | F6: =매출!H6 -> BLP-ES802S | G6: =매출!I6 -> 50 | H6: =매출!J6 -> 49800 | I6: =매출!L6 -> 2490000 | J6: =IF(O6=1,SUMIFS($I:$I,$A:$A,$A6),"") -> 2490000 | K6: =IF(O6=1,총정리!$B$19,"") -> 2750 | L6: =IF(O6=1,매출!Q6,"") -> 0 | M6: =IF(AND(K6<>"",L6<>""),K6*L6,"") -> 0 | N6: =IF(O6=1,E6+J6+M6,"") -> 2540000 | O6: =매출!U6 -> 1
A7: =매출!A7 -> 260106포뷰트올영 | B7: =매출!B7 -> 포뷰트 | C7: 950 | D7: =매출!D7 -> 100 | E7: =IF(AND(C7<>"",D7<>""),C7*D7,"") -> 95000 | F7: =매출!H7 -> 두피앰플 | G7: =매출!I7 -> 100 | H7: =매출!J7 -> 21800 | I7: =매출!L7 -> 2180000 | J7: =IF(O7=1,SUMIFS($I:$I,$A:$A,$A7),"") -> 2180000 | K7: =IF(O7=1,총정리!$B$19,"") -> 2750 | L7: =IF(O7=1,매출!Q7,"") -> 0 | M7: =IF(AND(K7<>"",L7<>""),K7*L7,"") -> 0 | N7: =IF(O7=1,E7+J7+M7,"") -> 2275000 | O7: =매출!U7 -> 1
A8: =매출!A8 -> 260106더포레쿠팡 | B8: =매출!B8 -> 더포레 | C8: 3000 | D8: =매출!D8 -> 80 | E8: =IF(AND(C8<>"",D8<>""),C8*D8,"") -> 240000 | F8: =매출!H8 -> 깍두기 | G8: =매출!I8 -> 30 | H8: =매출!J8 -> 8700 | I8: =매출!L8 -> 261000 | J8: =IF(O8=1,SUMIFS($I:$I,$A:$A,$A8),"") -> 826000 | K8: =IF(O8=1,총정리!$B$19,"") -> 2750 | L8: =IF(O8=1,매출!Q8,"") -> 0 | M8: =IF(AND(K8<>"",L8<>""),K8*L8,"") -> 0 | N8: =IF(O8=1,E8+J8+M8,"") -> 1066000 | O8: =매출!U8 -> 1
A9: =매출!A9 -> 260106더포레쿠팡 | B9: =매출!B9 -> 더포레 | D9: =매출!D9 -> 0 | E9: =IF(AND(C9<>"",D9<>""),C9*D9,"") | F9: =매출!H9 -> 멸치 | G9: =매출!I9 -> 30 | H9: =매출!J9 -> 9300 | I9: =매출!L9 -> 279000 | J9: =IF(O9=1,SUMIFS($I:$I,$A:$A,$A9),"") | K9: =IF(O9=1,총정리!$B$19,"") | L9: =IF(O9=1,매출!Q9,"") | M9: =IF(AND(K9<>"",L9<>""),K9*L9,"") | N9: =IF(O9=1,E9+J9+M9,"") | O9: =매출!U9 -> 0
A10: =매출!A10 -> 260106더포레쿠팡 | B10: =매출!B10 -> 더포레 | D10: =매출!D10 -> 0 | E10: =IF(AND(C10<>"",D10<>""),C10*D10,"") | F10: =매출!H10 -> 오이소박이 | G10: =매출!I10 -> 20 | H10: =매출!J10 -> 14300 | I10: =매출!L10 -> 286000 | J10: =IF(O10=1,SUMIFS($I:$I,$A:$A,$A10),"") | K10: =IF(O10=1,총정리!$B$19,"") | L10: =IF(O10=1,매출!Q10,"") | M10: =IF(AND(K10<>"",L10<>""),K10*L10,"") | N10: =IF(O10=1,E10+J10+M10,"") | O10: =매출!U10 -> 0
A11: =매출!A11 -> 260105케이에스쿠팡 | B11: =매출!B11 -> 케이에스 | C11: 3000 | D11: =매출!D11 -> 100 | E11: =IF(AND(C11<>"",D11<>""),C11*D11,"") -> 300000 | F11: =매출!H11 -> 베르베린 | G11: =매출!I11 -> 100 | H11: =매출!J11 -> 19500 | I11: =매출!L11 -> 1950000 | J11: =IF(O11=1,SUMIFS($I:$I,$A:$A,$A11),"") -> 1950000 | K11: =IF(O11=1,총정리!$B$19,"") -> 2750 | L11: =IF(O11=1,매출!Q11,"") -> 0 | M11: =IF(AND(K11<>"",L11<>""),K11*L11,"") -> 0 | N11: =IF(O11=1,E11+J11+M11,"") -> 2250000 | O11: =매출!U11 -> 1
A12: =매출!A12 -> 260105케이에스2쿠팡 | B12: =매출!B12 -> 케이에스 | C12: 3000 | D12: =매출!D12 -> 100 | E12: =IF(AND(C12<>"",D12<>""),C12*D12,"") -> 300000 | F12: =매출!H12 -> 위고핏 | G12: =매출!I12 -> 100 | H12: =매출!J12 -> 26500 | I12: =매출!L12 -> 2650000 | J12: =IF(O12=1,SUMIFS($I:$I,$A:$A,$A12),"") -> 2650000 | K12: =IF(O12=1,총정리!$B$19,"") -> 2750 | L12: =IF(O12=1,매출!Q12,"") -> 0 | M12: =IF(AND(K12<>"",L12<>""),K12*L12,"") -> 0 | N12: =IF(O12=1,E12+J12+M12,"") -> 2950000 | O12: =매출!U12 -> 1
A13: =매출!A13 -> 260106와이에이쿠팡 | B13: =매출!B13 -> 와이에이 | C13: 3000 | D13: =매출!D13 -> 60 | E13: =IF(AND(C13<>"",D13<>""),C13*D13,"") -> 180000 | F13: =매출!H13 -> 제품명모름 | G13: =매출!I13 -> 60 | H13: =매출!J13 -> 15900 | I13: =매출!L13 -> 954000 | J13: =IF(O13=1,SUMIFS($I:$I,$A:$A,$A13),"") -> 954000 | K13: =IF(O13=1,총정리!$B$19,"") -> 2750 | L13: =IF(O13=1,매출!Q13,"") -> 0 | M13: =IF(AND(K13<>"",L13<>""),K13*L13,"") -> 0 | N13: =IF(O13=1,E13+J13+M13,"") -> 1134000 | O13: =매출!U13 -> 1
A14: =매출!A14 -> 260105미올로쿠팡 | B14: =매출!B14 -> 미올로 | C14: 3000 | D14: =매출!D14 -> 100 | E14: =IF(AND(C14<>"",D14<>""),C14*D14,"") -> 300000 | F14: =매출!H14 -> W7 | G14: =매출!I14 -> 100 | H14: =매출!J14 -> 9900 | I14: =매출!L14 -> 990000 | J14: =IF(O14=1,SUMIFS($I:$I,$A:$A,$A14),"") -> 990000 | K14: =IF(O14=1,총정리!$B$19,"") -> 2750 | L14: =IF(O14=1,매출!Q14,"") -> 0 | M14: =IF(AND(K14<>"",L14<>""),K14*L14,"") -> 0 | N14: =IF(O14=1,E14+J14+M14,"") -> 1290000 | O14: =매출!U14 -> 1
A15: =매출!A15 -> 260105미올로2쿠팡 | B15: =매출!B15 -> 미올로 | C15: 3000 | D15: =매출!D15 -> 100 | E15: =IF(AND(C15<>"",D15<>""),C15*D15,"") -> 300000 | F15: =매출!H15 -> B7 | G15: =매출!I15 -> 100 | H15: =매출!J15 -> 9900 | I15: =매출!L15 -> 990000 | J15: =IF(O15=1,SUMIFS($I:$I,$A:$A,$A15),"") -> 990000 | K15: =IF(O15=1,총정리!$B$19,"") -> 2750 | L15: =IF(O15=1,매출!Q15,"") -> 0 | M15: =IF(AND(K15<>"",L15<>""),K15*L15,"") -> 0 | N15: =IF(O15=1,E15+J15+M15,"") -> 1290000 | O15: =매출!U15 -> 1
A16: =매출!A16 -> 260106꿈꾸던쿠팡 | B16: =매출!B16 -> 꿈꾸던 | C16: 3000 | D16: =매출!D16 -> 10 | E16: =IF(AND(C16<>"",D16<>""),C16*D16,"") -> 30000 | F16: =매출!H16 -> 제품명모름 | G16: =매출!I16 -> 10 | H16: =매출!J16 -> 8700 | I16: =매출!L16 -> 87000 | J16: =IF(O16=1,SUMIFS($I:$I,$A:$A,$A16),"") -> 87000 | K16: =IF(O16=1,총정리!$B$19,"") -> 2750 | L16: =IF(O16=1,매출!Q16,"") -> 0 | M16: =IF(AND(K16<>"",L16<>""),K16*L16,"") -> 0 | N16: =IF(O16=1,E16+J16+M16,"") -> 117000 | O16: =매출!U16 -> 1
A17: =매출!A17 -> 260106닥터메타쿠팡 | B17: =매출!B17 -> 닥터메타 | C17: 3000 | D17: =매출!D17 -> 20 | E17: =IF(AND(C17<>"",D17<>""),C17*D17,"") -> 60000 | F17: =매출!H17 -> 제품명모름 | G17: =매출!I17 -> 10 | H17: =매출!J17 -> 38000 | I17: =매출!L17 -> 380000 | J17: =IF(O17=1,SUMIFS($I:$I,$A:$A,$A17),"") -> 700000 | K17: =IF(O17=1,총정리!$B$19,"") -> 2750 | L17: =IF(O17=1,매출!Q17,"") -> 0 | M17: =IF(AND(K17<>"",L17<>""),K17*L17,"") -> 0 | N17: =IF(O17=1,E17+J17+M17,"") -> 760000 | O17: =매출!U17 -> 1
A18: =매출!A18 -> 260106닥터메타쿠팡 | B18: =매출!B18 -> 0 | D18: =매출!D18 -> 0 | E18: =IF(AND(C18<>"",D18<>""),C18*D18,"") | F18: =매출!H18 -> 제품명모름 | G18: =매출!I18 -> 5 | H18: =매출!J18 -> 35000 | I18: =매출!L18 -> 175000 | J18: =IF(O18=1,SUMIFS($I:$I,$A:$A,$A18),"") | K18: =IF(O18=1,총정리!$B$19,"") | L18: =IF(O18=1,매출!Q18,"") | M18: =IF(AND(K18<>"",L18<>""),K18*L18,"") | N18: =IF(O18=1,E18+J18+M18,"") | O18: =매출!U18 -> 0
A19: =매출!A19 -> 260106닥터메타쿠팡 | B19: =매출!B19 -> 0 | D19: =매출!D19 -> 0 | E19: =IF(AND(C19<>"",D19<>""),C19*D19,"") | F19: =매출!H19 -> 제품명모름 | G19: =매출!I19 -> 5 | H19: =매출!J19 -> 29000 | I19: =매출!L19 -> 145000 | J19: =IF(O19=1,SUMIFS($I:$I,$A:$A,$A19),"") | K19: =IF(O19=1,총정리!$B$19,"") | L19: =IF(O19=1,매출!Q19,"") | M19: =IF(AND(K19<>"",L19<>""),K19*L19,"") | N19: =IF(O19=1,E19+J19+M19,"") | O19: =매출!U19 -> 0
A20: =매출!A20 -> 260106오브제 | B20: =매출!B20 -> 오브제 | C20: 500 | D20: =매출!D20 -> 855 | E20: =IF(AND(C20<>"",D20<>""),C20*D20,"") -> 427500 | F20: =매출!H20 -> 12/31 오브제 포어 제로 오일 컨트롤 선크림 SPF50+ PA++++, 50ml, 1개 | G20: =매출!I20 -> 10 | H20: =매출!J20 -> 17900 | I20: =매출!L20 -> 179000 | J20: =IF(O20=1,SUMIFS($I:$I,$A:$A,$A20),"") -> 19068000 | K20: =IF(O20=1,총정리!$B$19,"") -> 2750 | L20: =IF(O20=1,매출!Q20,"") -> 0 | M20: =IF(AND(K20<>"",L20<>""),K20*L20,"") -> 0 | N20: =IF(O20=1,E20+J20+M20,"") -> 19495500 | O20: =매출!U20 -> 1
A21: =매출!A21 -> 260106오브제 | B21: =매출!B21 -> 오브제 | D21: =매출!D21 -> 0 | E21: =IF(AND(C21<>"",D21<>""),C21*D21,"") | F21: =매출!H21 -> 12/31 오브제 올인원 쿨 픽싱 미스트, 1개, 100ml | G21: =매출!I21 -> 5 | H21: =매출!J21 -> 15790 | I21: =매출!L21 -> 78950 | J21: =IF(O21=1,SUMIFS($I:$I,$A:$A,$A21),"") | K21: =IF(O21=1,총정리!$B$19,"") | L21: =IF(O21=1,매출!Q21,"") | M21: =IF(AND(K21<>"",L21<>""),K21*L21,"") | N21: =IF(O21=1,E21+J21+M21,"") | O21: =매출!U21 -> 0
A22: =매출!A22 -> 260106오브제 | B22: =매출!B22 -> 오브제 | D22: =매출!D22 -> 0 | E22: =IF(AND(C22<>"",D22<>""),C22*D22,"") | F22: =매출!H22 -> 12/31 오브제 올인원 더블 에센스 100ml | G22: =매출!I22 -> 5 | H22: =매출!J22 -> 25300 | I22: =매출!L22 -> 126500 | J22: =IF(O22=1,SUMIFS($I:$I,$A:$A,$A22),"") | K22: =IF(O22=1,총정리!$B$19,"") | L22: =IF(O22=1,매출!Q22,"") | M22: =IF(AND(K22<>"",L22<>""),K22*L22,"") | N22: =IF(O22=1,E22+J22+M22,"") | O22: =매출!U22 -> 0
A23: =매출!A23 -> 260106오브제 | B23: =매출!B23 -> 오브제 | D23: =매출!D23 -> 0 | E23: =IF(AND(C23<>"",D23<>""),C23*D23,"") | F23: =매출!H23 -> 12/31 오브제 오일 컨트롤 피니셔 5g 기름종이 팩트 파우더 | G23: =매출!I23 -> 10 | H23: =매출!J23 -> 16400 | I23: =매출!L23 -> 164000 | J23: =IF(O23=1,SUMIFS($I:$I,$A:$A,$A23),"") | K23: =IF(O23=1,총정리!$B$19,"") | L23: =IF(O23=1,매출!Q23,"") | M23: =IF(AND(K23<>"",L23<>""),K23*L23,"") | N23: =IF(O23=1,E23+J23+M23,"") | O23: =매출!U23 -> 0
A24: =매출!A24 -> 260106오브제 | B24: =매출!B24 -> 오브제 | D24: =매출!D24 -> 0 | E24: =IF(AND(C24<>"",D24<>""),C24*D24,"") | F24: =매출!H24 -> 12/31 오브제 씬 스틸 컨실러 5g | G24: =매출!I24 -> 3 | H24: =매출!J24 -> 14900 | I24: =매출!L24 -> 44700 | J24: =IF(O24=1,SUMIFS($I:$I,$A:$A,$A24),"") | K24: =IF(O24=1,총정리!$B$19,"") | L24: =IF(O24=1,매출!Q24,"") | M24: =IF(AND(K24<>"",L24<>""),K24*L24,"") | N24: =IF(O24=1,E24+J24+M24,"") | O24: =매출!U24 -> 0
A25: =매출!A25 -> 260106오브제 | B25: =매출!B25 -> 오브제 | D25: =매출!D25 -> 0 | E25: =IF(AND(C25<>"",D25<>""),C25*D25,"") | F25: =매출!H25 -> 12/31 오브제 씬 스틸 컨실러 5g | G25: =매출!I25 -> 5 | H25: =매출!J25 -> 14900 | I25: =매출!L25 -> 74500 | J25: =IF(O25=1,SUMIFS($I:$I,$A:$A,$A25),"") | K25: =IF(O25=1,총정리!$B$19,"") | L25: =IF(O25=1,매출!Q25,"") | M25: =IF(AND(K25<>"",L25<>""),K25*L25,"") | N25: =IF(O25=1,E25+J25+M25,"") | O25: =매출!U25 -> 0
A26: =매출!A26 -> 260106오브제 | B26: =매출!B26 -> 오브제 | D26: =매출!D26 -> 0 | E26: =IF(AND(C26<>"",D26<>""),C26*D26,"") | F26: =매출!H26 -> 12/31 오브제 무드 체인지 립밤, 웜 오렌지, 1개 | G26: =매출!I26 -> 15 | H26: =매출!J26 -> 11500 | I26: =매출!L26 -> 172500 | J26: =IF(O26=1,SUMIFS($I:$I,$A:$A,$A26),"") | K26: =IF(O26=1,총정리!$B$19,"") | L26: =IF(O26=1,매출!Q26,"") | M26: =IF(AND(K26<>"",L26<>""),K26*L26,"") | N26: =IF(O26=1,E26+J26+M26,"") | O26: =매출!U26 -> 0
A27: =매출!A27 -> 260106오브제 | B27: =매출!B27 -> 오브제 | D27: =매출!D27 -> 0 | E27: =IF(AND(C27<>"",D27<>""),C27*D27,"") | F27: =매출!H27 -> 12/29 오브제 포어 제로 필링 토너 310ml + 오일 컨트롤 로션 70ml + 클레이팩 100ml 기초 3종 세트 | G27: =매출!I27 -> 15 | H27: =매출!J27 -> 49900 | I27: =매출!L27 -> 748500 | J27: =IF(O27=1,SUMIFS($I:$I,$A:$A,$A27),"") | K27: =IF(O27=1,총정리!$B$19,"") | L27: =IF(O27=1,매출!Q27,"") | M27: =IF(AND(K27<>"",L27<>""),K27*L27,"") | N27: =IF(O27=1,E27+J27+M27,"") | O27: =매출!U27 -> 0
A28: =매출!A28 -> 260106오브제 | B28: =매출!B28 -> 오브제 | D28: =매출!D28 -> 0 | E28: =IF(AND(C28<>"",D28<>""),C28*D28,"") | F28: =매출!H28 -> 12/27 오브제 무드 체인지 립밤 (3종 택1) | G28: =매출!I28 -> 18 | H28: =매출!J28 -> 11500 | I28: =매출!L28 -> 207000 | J28: =IF(O28=1,SUMIFS($I:$I,$A:$A,$A28),"") | K28: =IF(O28=1,총정리!$B$19,"") | L28: =IF(O28=1,매출!Q28,"") | M28: =IF(AND(K28<>"",L28<>""),K28*L28,"") | N28: =IF(O28=1,E28+J28+M28,"") | O28: =매출!U28 -> 0
A29: =매출!A29 -> 260106오브제 | B29: =매출!B29 -> 오브제 | D29: =매출!D29 -> 0 | E29: =IF(AND(C29<>"",D29<>""),C29*D29,"") | F29: =매출!H29 -> 12/25 오브제 모이스처 프로틴 장벽 크림, 70ml, 2개 | G29: =매출!I29 -> 5 | H29: =매출!J29 -> 35800 | I29: =매출!L29 -> 179000 | J29: =IF(O29=1,SUMIFS($I:$I,$A:$A,$A29),"") | K29: =IF(O29=1,총정리!$B$19,"") | L29: =IF(O29=1,매출!Q29,"") | M29: =IF(AND(K29<>"",L29<>""),K29*L29,"") | N29: =IF(O29=1,E29+J29+M29,"") | O29: =매출!U29 -> 0
A30: =매출!A30 -> 260106오브제 | B30: =매출!B30 -> 오브제 | D30: =매출!D30 -> 0 | E30: =IF(AND(C30<>"",D30<>""),C30*D30,"") | F30: =매출!H30 -> 12/24 오브제 포어 제로 무스 클레이 팩 100ml | G30: =매출!I30 -> 15 | H30: =매출!J30 -> 21400 | I30: =매출!L30 -> 321000 | J30: =IF(O30=1,SUMIFS($I:$I,$A:$A,$A30),"") | K30: =IF(O30=1,총정리!$B$19,"") | L30: =IF(O30=1,매출!Q30,"") | M30: =IF(AND(K30<>"",L30<>""),K30*L30,"") | N30: =IF(O30=1,E30+J30+M30,"") | O30: =매출!U30 -> 0
A31: =매출!A31 -> 260106오브제 | B31: =매출!B31 -> 오브제 | D31: =매출!D31 -> 0 | E31: =IF(AND(C31<>"",D31<>""),C31*D31,"") | F31: =매출!H31 -> 12/24 오브제 오브제 맥스 워터풀 선크림 대용량 저자극 피부진정 올인원 SPF50+ PA++++, 1개, 300ml | G31: =매출!I31 -> 5 | H31: =매출!J31 -> 24900 | I31: =매출!L31 -> 124500 | J31: =IF(O31=1,SUMIFS($I:$I,$A:$A,$A31),"") | K31: =IF(O31=1,총정리!$B$19,"") | L31: =IF(O31=1,매출!Q31,"") | M31: =IF(AND(K31<>"",L31<>""),K31*L31,"") | N31: =IF(O31=1,E31+J31+M31,"") | O31: =매출!U31 -> 0
A32: =매출!A32 -> 260106오브제 | B32: =매출!B32 -> 오브제 | D32: =매출!D32 -> 0 | E32: =IF(AND(C32<>"",D32<>""),C32*D32,"") | F32: =매출!H32 -> 12/24 오브제 오브제 맥스 올인원 워시 남성용 페이스 바디 클렌저 샴푸, 1개, 500ml | G32: =매출!I32 -> 6 | H32: =매출!J32 -> 18900 | I32: =매출!L32 -> 113400 | J32: =IF(O32=1,SUMIFS($I:$I,$A:$A,$A32),"") | K32: =IF(O32=1,총정리!$B$19,"") | L32: =IF(O32=1,매출!Q32,"") | M32: =IF(AND(K32<>"",L32<>""),K32*L32,"") | N32: =IF(O32=1,E32+J32+M32,"") | O32: =매출!U32 -> 0
... A62: =매출!A62 -> 260106오브제 | B62: =매출!B62 -> 오브제 | D62: =매출!D62 -> 0 | E62: =IF(AND(C62<>"",D62<>""),C62*D62,"") | F62: =매출!H62 -> 1/1 오브제 내추럴 올인원 커버 로션 50g, 1개 | G62: =매출!I62 -> 30 | H62: =매출!J62 -> 25250 | I62: =매출!L62 -> 757500 | J62: =IF(O62=1,SUMIFS($I:$I,$A:$A,$A62),"") | K62: =IF(O62=1,총정리!$B$19,"") | L62: =IF(O62=1,매출!Q62,"") | M62: =IF(AND(K62<>"",L62<>""),K62*L62,"") | N62: =IF(O62=1,E62+J62+M62,"") | O62: =매출!U62 -> 0
A63: =매출!A63 -> 260106푸드올로지 | B63: =매출!B63 -> 푸드올로지 | C63: 500 | D63: =매출!D63 -> 1089 | E63: =IF(AND(C63<>"",D63<>""),C63*D63,"") -> 544500 | F63: =매출!H63 -> 12/31 푸드올로지 톡스올로지 클렌즈 비움, 450ml, 1개 | G63: =매출!I63 -> 3 | H63: =매출!J63 -> 28800 | I63: =매출!L63 -> 86400 | J63: =IF(O63=1,SUMIFS($I:$I,$A:$A,$A63),"") -> 31019310 | K63: =IF(O63=1,총정리!$B$19,"") -> 2750 | L63: =IF(O63=1,매출!Q63,"") -> 0 | M63: =IF(AND(K63<>"",L63<>""),K63*L63,"") -> 0 | N63: =IF(O63=1,E63+J63+M63,"") -> 31563810 | O63: =매출!U63 -> 1
A64: =매출!A64 -> 260106푸드올로지 | B64: =매출!B64 -> 푸드올로지 | D64: =매출!D64 -> 0 | E64: =IF(AND(C64<>"",D64<>""),C64*D64,"") | F64: =매출!H64 -> 12/31 푸드올로지 톡스올로지 48시간 CCA 클렌즈주스, 1L, 1개 | G64: =매출!I64 -> 5 | H64: =매출!J64 -> 24800 | I64: =매출!L64 -> 124000 | J64: =IF(O64=1,SUMIFS($I:$I,$A:$A,$A64),"") | K64: =IF(O64=1,총정리!$B$19,"") | L64: =IF(O64=1,매출!Q64,"") | M64: =IF(AND(K64<>"",L64<>""),K64*L64,"") | N64: =IF(O64=1,E64+J64+M64,"") | O64: =매출!U64 -> 0
A65: =매출!A65 -> 260106푸드올로지 | B65: =매출!B65 -> 푸드올로지 | D65: =매출!D65 -> 0 | E65: =IF(AND(C65<>"",D65<>""),C65*D65,"") | F65: =매출!H65 -> 12/31 푸드올로지 톡스올로지 48시간 CCA 클렌즈주스, 1L, 1개 | G65: =매출!I65 -> 10 | H65: =매출!J65 -> 24800 | I65: =매출!L65 -> 248000 | J65: =IF(O65=1,SUMIFS($I:$I,$A:$A,$A65),"") | K65: =IF(O65=1,총정리!$B$19,"") | L65: =IF(O65=1,매출!Q65,"") | M65: =IF(AND(K65<>"",L65<>""),K65*L65,"") | N65: =IF(O65=1,E65+J65+M65,"") | O65: =매출!U65 -> 0
A66: =매출!A66 -> 260106푸드올로지 | B66: =매출!B66 -> 푸드올로지 | D66: =매출!D66 -> 0 | E66: =IF(AND(C66<>"",D66<>""),C66*D66,"") | F66: =매출!H66 -> 12/31 푸드올로지 콜레올로지컷 프로 다이어트 보조제 39.6g, 66정, 1개 | G66: =매출!I66 -> 5 | H66: =매출!J66 -> 34190 | I66: =매출!L66 -> 170950 | J66: =IF(O66=1,SUMIFS($I:$I,$A:$A,$A66),"") | K66: =IF(O66=1,총정리!$B$19,"") | L66: =IF(O66=1,매출!Q66,"") | M66: =IF(AND(K66<>"",L66<>""),K66*L66,"") | N66: =IF(O66=1,E66+J66+M66,"") | O66: =매출!U66 -> 0
A67: =매출!A67 -> 260106푸드올로지 | B67: =매출!B67 -> 푸드올로지 | D67: =매출!D67 -> 0 | E67: =IF(AND(C67<>"",D67<>""),C67*D67,"") | F67: =매출!H67 -> 12/31 푸드올로지 콜레올로지컷 다이어트 유산균, 20정, 1개 | G67: =매출!I67 -> 3 | H67: =매출!J67 -> 29800 | I67: =매출!L67 -> 89400 | J67: =IF(O67=1,SUMIFS($I:$I,$A:$A,$A67),"") | K67: =IF(O67=1,총정리!$B$19,"") | L67: =IF(O67=1,매출!Q67,"") | M67: =IF(AND(K67<>"",L67<>""),K67*L67,"") | N67: =IF(O67=1,E67+J67+M67,"") | O67: =매출!U67 -> 0
A68: =매출!A68 -> 260106푸드올로지 | B68: =매출!B68 -> 푸드올로지 | D68: =매출!D68 -> 0 | E68: =IF(AND(C68<>"",D68<>""),C68*D68,"") | F68: =매출!H68 -> 12/31 푸드올로지 콜레 티 워터, 500ml, 12개 | G68: =매출!I68 -> 3 | H68: =매출!J68 -> 16900 | I68: =매출!L68 -> 50700 | J68: =IF(O68=1,SUMIFS($I:$I,$A:$A,$A68),"") | K68: =IF(O68=1,총정리!$B$19,"") | L68: =IF(O68=1,매출!Q68,"") | M68: =IF(AND(K68<>"",L68<>""),K68*L68,"") | N68: =IF(O68=1,E68+J68+M68,"") | O68: =매출!U68 -> 0
A69: =매출!A69 -> 260106푸드올로지 | B69: =매출!B69 -> 푸드올로지 | D69: =매출!D69 -> 0 | E69: =IF(AND(C69<>"",D69<>""),C69*D69,"") | F69: =매출!H69 -> 12/31 푸드올로지 콜라겐 센텔라 젤리, 1개, 10회분 | G69: =매출!I69 -> 10 | H69: =매출!J69 -> 22800 | I69: =매출!L69 -> 228000 | J69: =IF(O69=1,SUMIFS($I:$I,$A:$A,$A69),"") | K69: =IF(O69=1,총정리!$B$19,"") | L69: =IF(O69=1,매출!Q69,"") | M69: =IF(AND(K69<>"",L69<>""),K69*L69,"") | N69: =IF(O69=1,E69+J69+M69,"") | O69: =매출!U69 -> 0
...

Sheet 총정리
A1: 전체 요약
A2: 총 매출액 공급가 | B2: =SUM(매출!F:F)+SUM(매출!L:L)+SUM(매출!S:S) -> 261086220
A3: 총 매출 입금액(+vat) | B3: =SUM(매출!G:G)+SUM(매출!M:M)+SUM(매출!T:T) -> 287194842
A4: 부가세(매출입금액*10%) | B4: =B2*0.1 -> 26108622
A5: 총 지출 액 | B5: =SUM(지출!N:N) -> #VALUE! | C5: (급여/세금 등 추가지출 포함)
A6: 순 마진(공급가-총지출) | B6: =B2-B5 -> #VALUE!
A7: 정산ID별 요약
A8: 정산ID | B8: 업체명 | C8: 매출 공급가 | D8: 매출 입금액(+vat) | E8: 총 지출 | F8: 순 마진
B9: {=IF($A9="","",INDEX(매출!B:B,MATCH($A9,매출!A:A,0)))} | C9: =IF($A9="","",SUMIFS(매출!F:F,매출!A:A,$A9)+SUMIFS(매출!S:S,매출!A:A,$A9)+SUMIFS(매출!L:L,매출!A:A,$A9)) | D9: =IF($A9="","",SUMIFS(매출!G:G,매출!A:A,$A9)+SUMIFS(매출!T:T,매출!A:A,$A9)+SUMIFS(매출!M:M,매출!A:A,$A9)) | E9: =IF($A9="","",SUMIFS(지출!N:N,지출!A:A,$A9)) | F9: =IF($A9="","",C9-E9)
B10: {=IF($A10="","",INDEX(매출!B:B,MATCH($A10,매출!A:A,0)))} | C10: =IF($A10="","",SUMIFS(매출!F:F,매출!A:A,$A10)+SUMIFS(매출!S:S,매출!A:A,$A10)+SUMIFS(매출!L:L,매출!A:A,$A10)) | D10: =IF($A10="","",SUMIFS(매출!G:G,매출!A:A,$A10)+SUMIFS(매출!T:T,매출!A:A,$A10)+SUMIFS(매출!M:M,매출!A:A,$A10)) | E10: =IF($A10="","",SUMIFS(지출!N:N,지출!A:A,$A10)) | F10: =IF($A10="","",C10-E10)
B11: {=IF($A11="","",INDEX(매출!B:B,MATCH($A11,매출!A:A,0)))} | C11: =IF($A11="","",SUMIFS(매출!F:F,매출!A:A,$A11)+SUMIFS(매출!S:S,매출!A:A,$A11)+SUMIFS(매출!L:L,매출!A:A,$A11)) | D11: =IF($A11="","",SUMIFS(매출!G:G,매출!A:A,$A11)+SUMIFS(매출!T:T,매출!A:A,$A11)+SUMIFS(매출!M:M,매출!A:A,$A11)) | E11: =IF($A11="","",SUMIFS(지출!N:N,지출!A:A,$A11)) | F11: =IF($A11="","",C11-E11)
A12: 메모 | B12: {=IF($A12="","",INDEX(매출!B:B,MATCH($A12,매출!A:A,0)))} -> #N/A | C12: =IF($A12="","",SUMIFS(매출!F:F,매출!A:A,$A12)+SUMIFS(매출!S:S,매출!A:A,$A12)+SUMIFS(매출!L:L,매출!A:A,$A12)) -> 0 | D12: =IF($A12="","",SUMIFS(매출!G:G,매출!A:A,$A12)+SUMIFS(매출!T:T,매출!A:A,$A12)+SUMIFS(매출!M:M,매출!A:A,$A12)) -> 0 | E12: =IF($A12="","",SUMIFS(지출!N:N,지출!A:A,$A12)) -> 0 | F12: =IF($A12="","",C12-E12) -> 0
A13: • 매출 탭: 같은 정산 건은 '정산ID'를 동일하게 입력하세요. 진행비/택배대행은 보통 첫 행(해당 정산ID의 첫 줄)에만 입력하면 중복 합산이 없습니다. | B13: {=IF($A13="","",INDEX(매출!B:B,MATCH($A13,매출!A:A,0)))} -> #N/A | C13: =IF($A13="","",SUMIFS(매출!F:F,매출!A:A,$A13)+SUMIFS(매출!S:S,매출!A:A,$A13)+SUMIFS(매출!L:L,매출!A:A,$A13)) -> 0 | D13: =IF($A13="","",SUMIFS(매출!G:G,매출!A:A,$A13)+SUMIFS(매출!T:T,매출!A:A,$A13)+SUMIFS(매출!M:M,매출!A:A,$A13)) -> 0 | E13: =IF($A13="","",SUMIFS(지출!N:N,지출!A:A,$A13)) -> 0 | F13: =IF($A13="","",C13-E13) -> 0
A14: • 지출 탭: 진행비(실비)만 직접 입력하면 나머지는 매출에서 자동으로 따라옵니다. (택배대행 실비+vat은 2,750원 고정) | B14: {=IF($A14="","",INDEX(매출!B:B,MATCH($A14,매출!A:A,0)))} -> #N/A | C14: =IF($A14="","",SUMIFS(매출!F:F,매출!A:A,$A14)+SUMIFS(매출!S:S,매출!A:A,$A14)+SUMIFS(매출!L:L,매출!A:A,$A14)) -> 0 | D14: =IF($A14="","",SUMIFS(매출!G:G,매출!A:A,$A14)+SUMIFS(매출!T:T,매출!A:A,$A14)+SUMIFS(매출!M:M,매출!A:A,$A14)) -> 0 | E14: =IF($A14="","",SUMIFS(지출!N:N,지출!A:A,$A14)) -> 0 | F14: =IF($A14="","",C14-E14) -> 0
A15: • 총정리 탭: 전체/정산ID별 매출·지출·마진이 자동 집계됩니다. | B15: {=IF($A15="","",INDEX(매출!B:B,MATCH($A15,매출!A:A,0)))} -> #N/A | C15: =IF($A15="","",SUMIFS(매출!F:F,매출!A:A,$A15)+SUMIFS(매출!S:S,매출!A:A,$A15)+SUMIFS(매출!L:L,매출!A:A,$A15)) -> 0 | D15: =IF($A15="","",SUMIFS(매출!G:G,매출!A:A,$A15)+SUMIFS(매출!T:T,매출!A:A,$A15)+SUMIFS(매출!M:M,매출!A:A,$A15)) -> 0 | E15: =IF($A15="","",SUMIFS(지출!N:N,지출!A:A,$A15)) -> 0 | F15: =IF($A15="","",C15-E15) -> 0
B16: {=IF($A16="","",INDEX(매출!B:B,MATCH($A16,매출!A:A,0)))} | C16: =IF($A16="","",SUMIFS(매출!F:F,매출!A:A,$A16)+SUMIFS(매출!S:S,매출!A:A,$A16)+SUMIFS(매출!L:L,매출!A:A,$A16)) | D16: =IF($A16="","",SUMIFS(매출!G:G,매출!A:A,$A16)+SUMIFS(매출!T:T,매출!A:A,$A16)+SUMIFS(매출!M:M,매출!A:A,$A16)) | E16: =IF($A16="","",SUMIFS(지출!N:N,지출!A:A,$A16)) | F16: =IF($A16="","",C16-E16)
B17: {=IF($A17="","",INDEX(매출!B:B,MATCH($A17,매출!A:A,0)))} | C17: =IF($A17="","",SUMIFS(매출!F:F,매출!A:A,$A17)+SUMIFS(매출!S:S,매출!A:A,$A17)+SUMIFS(매출!L:L,매출!A:A,$A17)) | D17: =IF($A17="","",SUMIFS(매출!G:G,매출!A:A,$A17)+SUMIFS(매출!T:T,매출!A:A,$A17)+SUMIFS(매출!M:M,매출!A:A,$A17)) | E17: =IF($A17="","",SUMIFS(지출!N:N,지출!A:A,$A17)) | F17: =IF($A17="","",C17-E17)
A18: 설정값 | B18: {=IF($A18="","",INDEX(매출!B:B,MATCH($A18,매출!A:A,0)))} -> #N/A | C18: =IF($A18="","",SUMIFS(매출!F:F,매출!A:A,$A18)+SUMIFS(매출!S:S,매출!A:A,$A18)+SUMIFS(매출!L:L,매출!A:A,$A18)) -> 0 | D18: =IF($A18="","",SUMIFS(매출!G:G,매출!A:A,$A18)+SUMIFS(매출!T:T,매출!A:A,$A18)+SUMIFS(매출!M:M,매출!A:A,$A18)) -> 0 | E18: =IF($A18="","",SUMIFS(지출!N:N,지출!A:A,$A18)) -> 0 | F18: =IF($A18="","",C18-E18) -> 0
A19: 택배대행(실비)+vat 단가 | B19: 2750 | C19: =IF($A19="","",SUMIFS(매출!F:F,매출!A:A,$A19)+SUMIFS(매출!S:S,매출!A:A,$A19)+SUMIFS(매출!L:L,매출!A:A,$A19)) -> 0 | D19: =IF($A19="","",SUMIFS(매출!G:G,매출!A:A,$A19)+SUMIFS(매출!T:T,매출!A:A,$A19)+SUMIFS(매출!M:M,매출!A:A,$A19)) -> 0 | E19: =IF($A19="","",SUMIFS(지출!N:N,지출!A:A,$A19)) -> 0 | F19: =IF($A19="","",C19-E19) -> 0
B20: {=IF($A20="","",INDEX(매출!B:B,MATCH($A20,매출!A:A,0)))} | C20: =IF($A20="","",SUMIFS(매출!F:F,매출!A:A,$A20)+SUMIFS(매출!S:S,매출!A:A,$A20)+SUMIFS(매출!L:L,매출!A:A,$A20)) | D20: =IF($A20="","",SUMIFS(매출!G:G,매출!A:A,$A20)+SUMIFS(매출!T:T,매출!A:A,$A20)+SUMIFS(매출!M:M,매출!A:A,$A20)) | E20: =IF($A20="","",SUMIFS(지출!N:N,지출!A:A,$A20)) | F20: =IF($A20="","",C20-E20)
B21: {=IF($A21="","",INDEX(매출!B:B,MATCH($A21,매출!A:A,0)))} | C21: =IF($A21="","",SUMIFS(매출!F:F,매출!A:A,$A21)+SUMIFS(매출!S:S,매출!A:A,$A21)+SUMIFS(매출!L:L,매출!A:A,$A21)) | D21: =IF($A21="","",SUMIFS(매출!G:G,매출!A:A,$A21)+SUMIFS(매출!T:T,매출!A:A,$A21)+SUMIFS(매출!M:M,매출!A:A,$A21)) | E21: =IF($A21="","",SUMIFS(지출!N:N,지출!A:A,$A21)) | F21: =IF($A21="","",C21-E21)
B22: {=IF($A22="","",INDEX(매출!B:B,MATCH($A22,매출!A:A,0)))} | C22: =IF($A22="","",SUMIFS(매출!F:F,매출!A:A,$A22)+SUMIFS(매출!S:S,매출!A:A,$A22)+SUMIFS(매출!L:L,매출!A:A,$A22)) | D22: =IF($A22="","",SUMIFS(매출!G:G,매출!A:A,$A22)+SUMIFS(매출!T:T,매출!A:A,$A22)+SUMIFS(매출!M:M,매출!A:A,$A22)) | E22: =IF($A22="","",SUMIFS(지출!N:N,지출!A:A,$A22)) | F22: =IF($A22="","",C22-E22)
B23: {=IF($A23="","",INDEX(매출!B:B,MATCH($A23,매출!A:A,0)))} | C23: =IF($A23="","",SUMIFS(매출!F:F,매출!A:A,$A23)+SUMIFS(매출!S:S,매출!A:A,$A23)+SUMIFS(매출!L:L,매출!A:A,$A23)) | D23: =IF($A23="","",SUMIFS(매출!G:G,매출!A:A,$A23)+SUMIFS(매출!T:T,매출!A:A,$A23)+SUMIFS(매출!M:M,매출!A:A,$A23)) | E23: =IF($A23="","",SUMIFS(지출!N:N,지출!A:A,$A23)) | F23: =IF($A23="","",C23-E23)
B24: {=IF($A24="","",INDEX(매출!B:B,MATCH($A24,매출!A:A,0)))} | C24: =IF($A24="","",SUMIFS(매출!F:F,매출!A:A,$A24)+SUMIFS(매출!S:S,매출!A:A,$A24)+SUMIFS(매출!L:L,매출!A:A,$A24)) | D24: =IF($A24="","",SUMIFS(매출!G:G,매출!A:A,$A24)+SUMIFS(매출!T:T,매출!A:A,$A24)+SUMIFS(매출!M:M,매출!A:A,$A24)) | E24: =IF($A24="","",SUMIFS(지출!N:N,지출!A:A,$A24)) | F24: =IF($A24="","",C24-E24)
B25: {=IF($A25="","",INDEX(매출!B:B,MATCH($A25,매출!A:A,0)))} | C25: =IF($A25="","",SUMIFS(매출!F:F,매출!A:A,$A25)+SUMIFS(매출!S:S,매출!A:A,$A25)+SUMIFS(매출!L:L,매출!A:A,$A25)) | D25: =IF($A25="","",SUMIFS(매출!G:G,매출!A:A,$A25)+SUMIFS(매출!T:T,매출!A:A,$A25)+SUMIFS(매출!M:M,매출!A:A,$A25)) | E25: =IF($A25="","",SUMIFS(지출!N:N,지출!A:A,$A25)) | F25: =IF($A25="","",C25-E25)
B26: {=IF($A26="","",INDEX(매출!B:B,MATCH($A26,매출!A:A,0)))} | C26: =IF($A26="","",SUMIFS(매출!F:F,매출!A:A,$A26)+SUMIFS(매출!S:S,매출!A:A,$A26)+SUMIFS(매출!L:L,매출!A:A,$A26)) | D26: =IF($A26="","",SUMIFS(매출!G:G,매출!A:A,$A26)+SUMIFS(매출!T:T,매출!A:A,$A26)+SUMIFS(매출!M:M,매출!A:A,$A26)) | E26: =IF($A26="","",SUMIFS(지출!N:N,지출!A:A,$A26)) | F26: =IF($A26="","",C26-E26)
B27: {=IF($A27="","",INDEX(매출!B:B,MATCH($A27,매출!A:A,0)))} | C27: =IF($A27="","",SUMIFS(매출!F:F,매출!A:A,$A27)+SUMIFS(매출!S:S,매출!A:A,$A27)+SUMIFS(매출!L:L,매출!A:A,$A27)) | D27: =IF($A27="","",SUMIFS(매출!G:G,매출!A:A,$A27)+SUMIFS(매출!T:T,매출!A:A,$A27)+SUMIFS(매출!M:M,매출!A:A,$A27)) | E27: =IF($A27="","",SUMIFS(지출!N:N,지출!A:A,$A27)) | F27: =IF($A27="","",C27-E27)
B28: {=IF($A28="","",INDEX(매출!B:B,MATCH($A28,매출!A:A,0)))} | C28: =IF($A28="","",SUMIFS(매출!F:F,매출!A:A,$A28)+SUMIFS(매출!S:S,매출!A:A,$A28)+SUMIFS(매출!L:L,매출!A:A,$A28)) | D28: =IF($A28="","",SUMIFS(매출!G:G,매출!A:A,$A28)+SUMIFS(매출!T:T,매출!A:A,$A28)+SUMIFS(매출!M:M,매출!A:A,$A28)) | E28: =IF($A28="","",SUMIFS(지출!N:N,지출!A:A,$A28)) | F28: =IF($A28="","",C28-E28)
B29: {=IF($A29="","",INDEX(매출!B:B,MATCH($A29,매출!A:A,0)))} | C29: =IF($A29="","",SUMIFS(매출!F:F,매출!A:A,$A29)+SUMIFS(매출!S:S,매출!A:A,$A29)+SUMIFS(매출!L:L,매출!A:A,$A29)) | D29: =IF($A29="","",SUMIFS(매출!G:G,매출!A:A,$A29)+SUMIFS(매출!T:T,매출!A:A,$A29)+SUMIFS(매출!M:M,매출!A:A,$A29)) | E29: =IF($A29="","",SUMIFS(지출!N:N,지출!A:A,$A29)) | F29: =IF($A29="","",C29-E29)
B30: {=IF($A30="","",INDEX(매출!B:B,MATCH($A30,매출!A:A,0)))} | C30: =IF($A30="","",SUMIFS(매출!F:F,매출!A:A,$A30)+SUMIFS(매출!S:S,매출!A:A,$A30)+SUMIFS(매출!L:L,매출!A:A,$A30)) | D30: =IF($A30="","",SUMIFS(매출!G:G,매출!A:A,$A30)+SUMIFS(매출!T:T,매출!A:A,$A30)+SUMIFS(매출!M:M,매출!A:A,$A30)) | E30: =IF($A30="","",SUMIFS(지출!N:N,지출!A:A,$A30)) | F30: =IF($A30="","",C30-E30)
B31: {=IF($A31="","",INDEX(매출!B:B,MATCH($A31,매출!A:A,0)))} | C31: =IF($A31="","",SUMIFS(매출!F:F,매출!A:A,$A31)+SUMIFS(매출!S:S,매출!A:A,$A31)+SUMIFS(매출!L:L,매출!A:A,$A31)) | D31: =IF($A31="","",SUMIFS(매출!G:G,매출!A:A,$A31)+SUMIFS(매출!T:T,매출!A:A,$A31)+SUMIFS(매출!M:M,매출!A:A,$A31)) | E31: =IF($A31="","",SUMIFS(지출!N:N,지출!A:A,$A31)) | F31: =IF($A31="","",C31-E31)
... B208: {=IF($A208="","",INDEX(매출!B:B,MATCH($A208,매출!A:A,0)))} | C208: =IF($A208="","",SUMIFS(매출!F:F,매출!A:A,$A208)+SUMIFS(매출!S:S,매출!A:A,$A208)+SUMIFS(매출!L:L,매출!A:A,$A208)) | D208: =IF($A208="","",SUMIFS(매출!G:G,매출!A:A,$A208)+SUMIFS(매출!T:T,매출!A:A,$A208)+SUMIFS(매출!M:M,매출!A:A,$A208)) | E208: =IF($A208="","",SUMIFS(지출!N:N,지출!A:A,$A208)) | F208: =IF($A208="","",C208-E208)

Sheet 일자별 계산서 발행
A1: 일자별 계산서 발행 '라인업솔루션'에서 '강우메이커스'로 발행해야 하는 금액을 표기
A2: 날짜 | B2: 발행 요청 날짜 | C2: 발행 금액 | D2: 발행 확인 표기 | E2: 추가 및 수정 부분 표기
A3: 46028 | B3: 46024 | C3: 21286650 | D3: 완
A4: 46028 | B4: 46027 | C4: 3140280 | D4: 완
A5: 46028 | B5: 46028 | C5: 82013525 | D5: 완 | E5: 81670083
A6: 46029 | B6: 46029 | C6: 2136750 | D6: 완
A7: 46030 | B7: 46030 | C7: 55396754 | D7: 완 | E7: -1100000 /14일자에 반영 | F7: 57265544
A8: 46031 | B8: 46031 | C8: 7320830 | D8: 완
A9: 46034 | B9: 46034 | C9: 63231975 | D9: 완
A10: 46035 | B10: 46035 | C10: 8490152 | D10: 완
A11: 46036 | B11: 46036 | C11: 8998550 | D11: 완
A12: 46037 | B12: 46037 | C12: 15531010 | D12: 완
A13: 46038 | B13: 46038 | C13: 95679625 | D13: 완
A14: 46041 | B14: 46041 | C14: 4390650 | D14: 완
A15: 46042 | B15: 46042 | C15: 882750 | D15: 완
A16: 46043 | B16: 46043 | C16: 2128610 | D16: 완
A17: 46044 | B17: 46044 | C17: 167073940 | D17: 완
A18: 46045 | B18: 46045 | C18: 75369311 | D18: 완
C19: 14861055 | E19: 215921(23일 추가발행 금액)
A20: 46049 | B20: 46049 | C20: 3011749 | D20: 완
A21: 46050 | B21: 46050 | C21: 30947290 | D21: 완
A22: 46051 | B22: 46051 | C22: 61179604 | D22: 완
A23: 46052 | B23: 46052 | C23: 30462348 | D23: 완 | E23: 추가발행필요 9,733,042
A24: 46055 | B24: 46055 | C24: 6763790 | D24: 완
A25: 46056 | B25: 46056 | C25: 53535735 | D25: 완
A26: 46057 | B26: 46057 | C26: 475300 | D26: 완
A27: 46058 | B27: 46058 | C27: 86731282 | D27: 완
A28: 46059 | B28: 46059 | C28: 22548251 | D28: 완
A29: 46062 | B29: 46062 | C29: 19467691 | D29: 완
